[2024-10-07T21:56:35.556-0300] {local_task_job_runner.py:120} INFO - ::group::Pre task execution logs
[2024-10-07T21:56:35.596-0300] {taskinstance.py:2076} INFO - Dependencies all met for dep_context=non-requeueable deps ti=<TaskInstance: preprocess_predict.task_preprocess manual__2024-10-08T00:56:34.376436+00:00 [queued]>
[2024-10-07T21:56:35.610-0300] {taskinstance.py:2076} INFO - Dependencies all met for dep_context=requeueable deps ti=<TaskInstance: preprocess_predict.task_preprocess manual__2024-10-08T00:56:34.376436+00:00 [queued]>
[2024-10-07T21:56:35.612-0300] {taskinstance.py:2306} INFO - Starting attempt 1 of 2
[2024-10-07T21:56:35.629-0300] {taskinstance.py:2330} INFO - Executing <Task(_DockerDecoratedOperator): task_preprocess> on 2024-10-08 00:56:34.376436+00:00
[2024-10-07T21:56:35.637-0300] {warnings.py:110} WARNING - /home/***/.local/lib/python3.12/site-packages/***/task/task_runner/standard_task_runner.py:61: DeprecationWarning: This process (pid=1640) is multi-threaded, use of fork() may lead to deadlocks in the child.
  pid = os.fork()

[2024-10-07T21:56:35.639-0300] {standard_task_runner.py:63} INFO - Started process 1641 to run task
[2024-10-07T21:56:35.639-0300] {standard_task_runner.py:90} INFO - Running: ['***', 'tasks', 'run', 'preprocess_predict', 'task_preprocess', 'manual__2024-10-08T00:56:34.376436+00:00', '--job-id', '44', '--raw', '--subdir', 'DAGS_FOLDER/Predict/preprocess_predict.py', '--cfg-path', '/tmp/tmp7yb08e_n']
[2024-10-07T21:56:35.640-0300] {standard_task_runner.py:91} INFO - Job 44: Subtask task_preprocess
[2024-10-07T21:56:35.720-0300] {task_command.py:426} INFO - Running <TaskInstance: preprocess_predict.task_preprocess manual__2024-10-08T00:56:34.376436+00:00 [running]> on host 4a07270c49a4
[2024-10-07T21:56:35.814-0300] {taskinstance.py:2648} INFO - Exporting env vars: AIRFLOW_CTX_DAG_OWNER='***' AIRFLOW_CTX_DAG_ID='preprocess_predict' AIRFLOW_CTX_TASK_ID='task_preprocess' AIRFLOW_CTX_EXECUTION_DATE='2024-10-08T00:56:34.376436+00:00' AIRFLOW_CTX_TRY_NUMBER='1' AIRFLOW_CTX_DAG_RUN_ID='manual__2024-10-08T00:56:34.376436+00:00'
[2024-10-07T21:56:35.815-0300] {taskinstance.py:430} INFO - ::endgroup::
[2024-10-07T21:56:35.863-0300] {docker.py:366} INFO - Starting docker container from image pythondatapath:latest
[2024-10-07T21:56:35.873-0300] {docker.py:374} WARNING - Using remote engine or docker-in-docker and mounting temporary volume from host is not supported. Falling back to `mount_tmp_dir=False` mode. You can set `mount_tmp_dir` parameter to False to disable mounting and remove the warning
[2024-10-07T21:56:36.505-0300] {docker.py:436} INFO - + python3 -c 'import base64, os;x = base64.b64decode(os.environ["__PYTHON_SCRIPT"]);f = open("/tmp/script.py", "wb"); f.write(x);'
[2024-10-07T21:56:36.587-0300] {docker.py:436} INFO - + python3 -c 'import base64, os;x = base64.b64decode(os.environ["__PYTHON_INPUT"]);f = open("/tmp/script.in", "wb"); f.write(x);'
[2024-10-07T21:56:36.610-0300] {docker.py:436} INFO - + python3 /tmp/script.py /tmp/script.in /tmp/script.out
[2024-10-07T21:56:38.862-0300] {docker.py:436} INFO - Traceback (most recent call last):
  File "/tmp/script.py", line 60, in <module>
    res = task_preprocess(*arg_dict["args"], **arg_dict["kwargs"])
  File "/tmp/script.py", line 23, in task_preprocess
    df = pd.read_csv('/opt/***/dags/data/input/test.csv')
  File "/usr/local/lib/python3.8/site-packages/pandas/util/_decorators.py", line 211, in wrapper
[2024-10-07T21:56:38.863-0300] {docker.py:436} INFO - return func(*args, **kwargs)
  File "/usr/local/lib/python3.8/site-packages/pandas/util/_decorators.py", line 331, in wrapper
[2024-10-07T21:56:38.864-0300] {docker.py:436} INFO - return func(*args, **kwargs)
  File "/usr/local/lib/python3.8/site-packages/pandas/io/parsers/readers.py", line 950, in read_csv
[2024-10-07T21:56:38.866-0300] {docker.py:436} INFO - return _read(filepath_or_buffer, kwds)
  File "/usr/local/lib/python3.8/site-packages/pandas/io/parsers/readers.py", line 605, in _read
[2024-10-07T21:56:38.866-0300] {docker.py:436} INFO - parser = TextFileReader(filepath_or_buffer, **kwds)
  File "/usr/local/lib/python3.8/site-packages/pandas/io/parsers/readers.py", line 1442, in __init__
[2024-10-07T21:56:38.867-0300] {docker.py:436} INFO - self._engine = self._make_engine(f, self.engine)
  File "/usr/local/lib/python3.8/site-packages/pandas/io/parsers/readers.py", line 1735, in _make_engine
[2024-10-07T21:56:38.868-0300] {docker.py:436} INFO - self.handles = get_handle(
  File "/usr/local/lib/python3.8/site-packages/pandas/io/common.py", line 856, in get_handle
[2024-10-07T21:56:38.869-0300] {docker.py:436} INFO - handle = open(
FileNotFoundError: [Errno 2] No such file or directory: '/opt/***/dags/data/input/test.csv'

During handling of the above exception, another exception occurred:

Traceback (most recent call last):
  File "/tmp/script.py", line 62, in <module>
[2024-10-07T21:56:38.870-0300] {docker.py:436} INFO - with open(sys.argv[4], "w") as file:
IndexError: list index out of range
[2024-10-07T21:56:39.398-0300] {taskinstance.py:441} INFO - ::group::Post task execution logs
[2024-10-07T21:56:39.410-0300] {taskinstance.py:2905} ERROR - Task failed with exception
Traceback (most recent call last):
  File "/home/airflow/.local/lib/python3.12/site-packages/docker/api/client.py", line 265, in _raise_for_status
    response.raise_for_status()
  File "/home/airflow/.local/lib/python3.12/site-packages/requests/models.py", line 1021, in raise_for_status
    raise HTTPError(http_error_msg, response=self)
requests.exceptions.HTTPError: 400 Client Error: Bad Request for url: http+docker://localhost/v1.43/containers/create

The above exception was the direct cause of the following exception:

Traceback (most recent call last):
  File "/home/airflow/.local/lib/python3.12/site-packages/airflow/providers/docker/operators/docker.py", line 371, in _run_image
    return self._run_image_with_mounts([*self.mounts, tmp_mount], add_tmp_variable=True)
           ^^^^^^^^^^^^^^^^^^^^^^^^^^^^^^^^^^^^^^^^^^^^^^^^^^^^^^^^^^^^^^^^^^^^^^^^^^^^^
  File "/home/airflow/.local/lib/python3.12/site-packages/airflow/providers/docker/operators/docker.py", line 398, in _run_image_with_mounts
    self.container = self.cli.create_container(
                     ^^^^^^^^^^^^^^^^^^^^^^^^^^
  File "/home/airflow/.local/lib/python3.12/site-packages/docker/api/container.py", line 439, in create_container
    return self.create_container_from_config(config, name, platform)
           ^^^^^^^^^^^^^^^^^^^^^^^^^^^^^^^^^^^^^^^^^^^^^^^^^^^^^^^^^
  File "/home/airflow/.local/lib/python3.12/site-packages/docker/api/container.py", line 456, in create_container_from_config
    return self._result(res, True)
           ^^^^^^^^^^^^^^^^^^^^^^^
  File "/home/airflow/.local/lib/python3.12/site-packages/docker/api/client.py", line 271, in _result
    self._raise_for_status(response)
  File "/home/airflow/.local/lib/python3.12/site-packages/docker/api/client.py", line 267, in _raise_for_status
    raise create_api_error_from_http_exception(e) from e
          ^^^^^^^^^^^^^^^^^^^^^^^^^^^^^^^^^^^^^^^
  File "/home/airflow/.local/lib/python3.12/site-packages/docker/errors.py", line 39, in create_api_error_from_http_exception
    raise cls(e, response=response, explanation=explanation) from e
docker.errors.APIError: 400 Client Error for http+docker://localhost/v1.43/containers/create: Bad Request ("invalid mount config for type "bind": bind source path does not exist: /tmp/airflowtmpud_hovpc")

During handling of the above exception, another exception occurred:

Traceback (most recent call last):
  File "/home/airflow/.local/lib/python3.12/site-packages/airflow/models/taskinstance.py", line 465, in _execute_task
    result = _execute_callable(context=context, **execute_callable_kwargs)
             ^^^^^^^^^^^^^^^^^^^^^^^^^^^^^^^^^^^^^^^^^^^^^^^^^^^^^^^^^^^^^
  File "/home/airflow/.local/lib/python3.12/site-packages/airflow/models/taskinstance.py", line 432, in _execute_callable
    return execute_callable(context=context, **execute_callable_kwargs)
           ^^^^^^^^^^^^^^^^^^^^^^^^^^^^^^^^^^^^^^^^^^^^^^^^^^^^^^^^^^^^
  File "/home/airflow/.local/lib/python3.12/site-packages/airflow/models/baseoperator.py", line 400, in wrapper
    return func(self, *args, **kwargs)
           ^^^^^^^^^^^^^^^^^^^^^^^^^^^
  File "/home/airflow/.local/lib/python3.12/site-packages/airflow/providers/docker/decorators/docker.py", line 127, in execute
    return super().execute(context)
           ^^^^^^^^^^^^^^^^^^^^^^^^
  File "/home/airflow/.local/lib/python3.12/site-packages/airflow/models/baseoperator.py", line 400, in wrapper
    return func(self, *args, **kwargs)
           ^^^^^^^^^^^^^^^^^^^^^^^^^^^
  File "/home/airflow/.local/lib/python3.12/site-packages/airflow/decorators/base.py", line 265, in execute
    return_value = super().execute(context)
                   ^^^^^^^^^^^^^^^^^^^^^^^^
  File "/home/airflow/.local/lib/python3.12/site-packages/airflow/models/baseoperator.py", line 400, in wrapper
    return func(self, *args, **kwargs)
           ^^^^^^^^^^^^^^^^^^^^^^^^^^^
  File "/home/airflow/.local/lib/python3.12/site-packages/airflow/providers/docker/operators/docker.py", line 509, in execute
    return self._run_image()
           ^^^^^^^^^^^^^^^^^
  File "/home/airflow/.local/lib/python3.12/site-packages/airflow/providers/docker/operators/docker.py", line 380, in _run_image
    return self._run_image_with_mounts(self.mounts, add_tmp_variable=False)
           ^^^^^^^^^^^^^^^^^^^^^^^^^^^^^^^^^^^^^^^^^^^^^^^^^^^^^^^^^^^^^^^^
  File "/home/airflow/.local/lib/python3.12/site-packages/airflow/providers/docker/operators/docker.py", line 444, in _run_image_with_mounts
    raise DockerContainerFailedException(f"Docker container failed: {result!r}", logs=log_lines)
airflow.providers.docker.exceptions.DockerContainerFailedException: Docker container failed: {'StatusCode': 1}
[2024-10-07T21:56:39.420-0300] {taskinstance.py:1206} INFO - Marking task as UP_FOR_RETRY. dag_id=preprocess_predict, task_id=task_preprocess, run_id=manual__2024-10-08T00:56:34.376436+00:00, execution_date=20241008T005634, start_date=20241008T005635, end_date=20241008T005639
[2024-10-07T21:56:39.437-0300] {standard_task_runner.py:110} ERROR - Failed to execute job 44 for task task_preprocess (Docker container failed: {'StatusCode': 1}; 1641)
[2024-10-07T21:56:39.473-0300] {local_task_job_runner.py:240} INFO - Task exited with return code 1
[2024-10-07T21:56:39.504-0300] {taskinstance.py:3498} INFO - 0 downstream tasks scheduled from follow-on schedule check
[2024-10-07T21:56:39.506-0300] {local_task_job_runner.py:222} INFO - ::endgroup::
