[2024-10-07T21:49:35.097-0300] {task_context_logger.py:104} ERROR - Executor reports task instance <TaskInstance: preprocess_predict.preprocessvalues manual__2024-10-08T00:49:32.974904+00:00 [queued]> finished (failed) although the task says it's queued. (Info: None) Was the task killed externally?
